Workbook

Sheet CONFIG
A1: Hostplus Retirement Portfolios — Back-Test Model
A2: Configure inputs below, then view results on the DASHBOARD sheet.
A4: Input Parameter | B4: Value | C4: Description
A5: Starting Balance ($) | B5: 500000 | C5: Total portfolio balance at start of scenario
A6: Annual Drawdown Rate (%) | B6: 0.05 | C6: Percentage of balance drawn as pension each year
A7: CPIplus Spread (%) | B7: 0.025 | C7: Return above CPI for CPIplus option (currently 2.5%)
A8: Rebalance Lower Threshold (%) | B8: 0.18 | C8: Rebalance if CPIplus weight falls below this
A9: Rebalance Upper Threshold (%) | B9: 0.23 | C9: Rebalance if CPIplus weight rises above this
A10: Scenario | B10: Full Period | C10: Select market period to back-test
A11: Drawdown Recalculation | B11: Annual | C11: Annual: recalculate on 1 July each year. Fixed: use starting balance only.
A13: Derived Values (calculated)
A14: Monthly Payment ($) | B14: =B5*B6/12
A15: Annual Payment ($) | B15: =B5*B6
A17: Scenario Date Lookup
A18: Scenario | B18: Start Date | C18: End Date
A19: Full Period | B19: 37135 | C19: 45627
A20: GFC | B20: 39083 | C20: 41244
A21: COVID | B21: 43466 | C21: 44896
A22: Rising Rates | B22: 44562 | C22: 45627
A23: Bull Market | B23: 40909 | C23: 43800

Sheet DATA
A1: Historical Return Data
A3: Date | B3: Month # | C3: Growth Return | D3: Balanced Return | E3: Conservative Return | F3: CPIplus Return | G3: Cash Return | H3: CPI Index | I3: CPI Quarterly Change | J3: CPI 2Q Average | K3: CPI Annualised
A4: 37135 | B4: 1 | C4: -0.054297362 | D4: -0.0399764 | E4: -0.028222943 | F4: 0.0031789698 | G4: 0.0036748094 | H4: 73.5 | I4: -0.0027137042 | J4: 0.0034376684 | K4: 0.013821742
A5: 37165 | B5: 2 | C5: 0.038382477 | D5: 0.030206694 | E5: 0.023424183 | F5: 0.0031789698 | G5: 0.0036748094
A6: 37196 | B6: 3 | C6: 0.020186157 | D6: 0.016344079 | E6: 0.013184807 | F6: 0.0031789698 | G6: 0.003474495
A7: 37226 | B7: 4 | C7: 0.015817146 | D7: 0.013059115 | E7: 0.010773645 | F7: 0.0027256937 | G7: 0.003474495 | H7: 74 | I7: 0.0068027211 | J7: 0.0020445084 | K7: 0.0082031481
A8: 37257 | B8: 5 | C8: -0.017908115 | D8: -0.012299823 | E8: -0.0078402401 | F8: 0.0027256937 | G8: 0.003474495
A9: 37288 | B9: 6 | C9: -0.0076034591 | D9: -0.0047045692 | E9: -0.0023059178 | F9: 0.0027256937 | G9: 0.003474495
A10: 37316 | B10: 7 | C10: 0.022023908 | D10: 0.017588711 | E10: 0.014061889 | F10: 0.0042648573 | G10: 0.003474495 | H10: 74.5 | I10: 0.0067567568 | J10: 0.0067797389 | K10: 0.027395993
A11: 37347 | B11: 8 | C11: -0.0074877623 | D11: -0.0046406556 | E11: -0.0022651435 | F11: 0.0042648573 | G11: 0.003474495
A12: 37377 | B12: 9 | C12: -0.0037799182 | D12: -0.0017071319 | E12: -5.7163496e-05 | F12: 0.0042648573 | G12: 0.0036748094
A13: 37408 | B13: 10 | C13: -0.040713848 | D13: -0.029653896 | E13: -0.020601151 | F13: 0.0035960798 | G13: 0.003874685 | H13: 74.7 | I13: 0.0026845638 | J13: 0.0047206603 | K13: 0.01901677
A14: 37438 | B14: 11 | C14: -0.053023094 | D14: -0.038854055 | E14: -0.027339462 | F14: 0.0035960798 | G14: 0.003874685
A15: 37469 | B15: 12 | C15: 0.014017987 | D15: 0.011683481 | E15: 0.0097898585 | F15: 0.0035960798 | G15: 0.003874685
A16: 37500 | B16: 13 | C16: -0.062040934 | D16: -0.045654727 | E16: -0.032336565 | F16: 0.0038032815 | G16: 0.003874685 | H16: 75.3 | I16: 0.0080321285 | J16: 0.0053583461 | K16: 0.021606272
A17: 37530 | B17: 14 | C17: 0.026223096 | D17: 0.020903566 | E17: 0.016568922 | F17: 0.0038032815 | G17: 0.003874685
A18: 37561 | B18: 15 | C18: 0.020023946 | D18: 0.016163427 | E18: 0.013068613 | F18: 0.0038032815 | G18: 0.003874685
A19: 37591 | B19: 16 | C19: -0.022565659 | D19: -0.01589786 | E19: -0.010474753 | F19: 0.0042299186 | G19: 0.003874685 | H19: 75.7 | I19: 0.005312085 | J19: 0.0066721068 | K19: 0.026956719
A20: 37622 | B20: 17 | C20: -0.04188753 | D20: -0.03044009 | E20: -0.021202609 | F20: 0.0042299186 | G20: 0.003874685
A21: 37653 | B21: 18 | C21: -0.037741624 | D21: -0.027510981 | E21: -0.019102681 | F21: 0.0042299186 | G21: 0.003874685
A22: 37681 | B22: 19 | C22: 0.01082081 | D22: 0.009325122 | E22: 0.0080209348 | F22: 0.0052837789 | G22: 0.003874685 | H22: 76.8 | I22: 0.014531044 | J22: 0.0099215643 | K22: 0.040280798
A23: 37712 | B23: 20 | C23: 0.047234221 | D23: 0.036696637 | E23: 0.028109767 | F23: 0.0052837789 | G23: 0.003874685
A24: 37742 | B24: 21 | C24: 0.010928996 | D24: 0.0092615925 | E24: 0.0079357682 | F24: 0.0052837789 | G24: 0.003874685
A25: 37773 | B25: 22 | C25: 0.0011457213 | D25: 0.0019447211 | E25: 0.0025755516 | F25: 0.0044225214 | G25: 0.003874685 | H25: 76.8 | I25: 0 | J25: 0.0072655218 | K25: 0.029380351
A26: 37803 | B26: 23 | C26: 0.025864275 | D26: 0.02061482 | E26: 0.01630194 | F26: 0.0044225214 | G26: 0.003874685
A27: 37834 | B27: 24 | C27: 0.031512826 | D27: 0.024817594 | E27: 0.019375003 | F27: 0.0044225214 | G27: 0.003874685
A28: 37865 | B28: 25 | C28: -0.0025187824 | D28: -0.0008772516 | E28: 0.00048647968 | F28: 0.0026959486 | G28: 0.003874685 | H28: 77.1 | I28: 0.00390625 | J28: 0.001953125 | K28: 0.007835418
A29: 37895 | B29: 26 | C29: 0.025471257 | D29: 0.020324167 | E29: 0.01608989 | F29: 0.0026959486 | G29: 0.003874685
A30: 37926 | B30: 27 | C30: -0.011625801 | D30: -0.0077686941 | E30: -0.0045676039 | F30: 0.0026959486 | G30: 0.0040741238
A31: 37956 | B31: 28 | C31: 0.043220695 | D31: 0.033697317 | E31: 0.025945028 | F31: 0.0035396912 | G31: 0.0042731278 | H31: 77.5 | I31: 0.0051880674 | J31: 0.0045471587 | K31: 0.018313071
A32: 37987 | B32: 29 | C32: -0.010555974 | D32: -0.0068560858 | E32: -0.0038530408 | F32: 0.0035396912 | G32: 0.0042731278
A33: 38018 | B33: 30 | C33: 0.022754467 | D33: 0.01830426 | E33: 0.014645217 | F33: 0.0035396912 | G33: 0.0042731278
A34: 38047 | B34: 31 | C34: 0.019342194 | D34: 0.015691048 | E34: 0.01271446 | F34: 0.0039531861 | G34: 0.0042731278 | H34: 78 | I34: 0.0064516129 | J34: 0.0058198402 | K34: 0.023483374
A35: 38078 | B35: 32 | C35: -0.0084570842 | D35: -0.0052610226 | E35: -0.0026777556 | F35: 0.0039531861 | G35: 0.0042731278
A36: 38108 | B36: 33 | C36: 0.02975706 | D36: 0.023508146 | E36: 0.018448584 | F36: 0.0039531861 | G36: 0.0042731278
A37: 38139 | B37: 34 | C37: 0.034199014 | D37: 0.026857331 | E37: 0.020909378 | F37: 0.004359705 | G37: 0.0042731278 | H37: 78.6 | I37: 0.0076923077 | J37: 0.0070719603 | K37: 0.028589334
A38: 38169 | B38: 35 | C38: -0.016953809 | D38: -0.011607809 | E38: -0.0073251968 | F38: 0.004359705 | G38: 0.0042731278
A39: 38200 | B39: 36 | C39: 0.0062525318 | D39: 0.0058158894 | E39: 0.0054572332 | F39: 0.004359705 | G39: 0.0042731278
A40: 38231 | B40: 37 | C40: 0.022435226 | D40: 0.018087487 | E40: 0.014492292 | F40: 0.0037253313 | G40: 0.0042731278 | H40: 78.8 | I40: 0.0025445293 | J40: 0.0051184185 | K40: 0.0206314
A41: 38261 | B41: 38 | C41: 0.02494283 | D41: 0.019965121 | E41: 0.015868405 | F41: 0.0037253313 | G41: 0.0042731278
...

Sheet ENGINE
A1: Retirement Portfolios — Monthly Simulation Engine
A2: Retirement Portfolio: 80% Growth / 20% CPIplus | R2: Retirement Portfolio: 80% Balanced / 20% CPIplus | AI2: Retirement Portfolio: 80% Conservative / 20% CPIplus
A3: Date | B3: Month # | C3: Growth Open | D3: CPIplus Open | E3: Total Open | F3: Growth Return | G3: CPIplus Return | H3: Growth Post-Return | I3: CPIplus Post-Return | J3: Monthly Payment | K3: CPIplus Post-Drawdown | L3: Qtr-End? | M3: CPIplus Weight | N3: Rebalance? | O3: Growth Close | P3: CPIplus Close | R3: Date | S3: Month # | T3: Balanced Open | U3: CPIplus Open | V3: Total Open | W3: Balanced Return | X3: CPIplus Return | Y3: Balanced Post-Return | Z3: CPIplus Post-Return | AA3: Monthly Payment | AB3: CPIplus Post-Drawdown | AC3: Qtr-End? | AD3: CPIplus Weight | AE3: Rebalance? | AF3: Balanced Close | AG3: CPIplus Close | AI3: Date | AJ3: Month # | AK3: Conservative Open | AL3: CPIplus Open | AM3: Total Open | AN3: Conservative Return | AO3: CPIplus Return | AP3: Conservative Post-Return | AQ3: CPIplus Post-Return | AR3: Monthly Payment | AS3: CPIplus Post-Drawdown | AT3: Qtr-End? | AU3: CPIplus Weight | AV3: Rebalance? | AW3: Conservative Close | AX3: CPIplus Close
A4: =DATA!A4 | B4: =DATA!B4 | C4: =CONFIG!$B$5*0.8 | D4: =CONFIG!$B$5*0.2 | E4: =C4+D4 | F4: =DATA!C4 | G4: =DATA!F4 | H4: =C4*(1+F4) | I4: =D4*(1+G4) | J4: =CONFIG!$B$5*CONFIG!$B$6/12 | K4: =MAX(0,I4-J4) | L4: =IF(OR(MONTH(A4)=3,MONTH(A4)=6,MONTH(A4)=9,MONTH(A4)=12),"Y","N") | M4: =IF((H4+K4)=0,0,K4/(H4+K4)) | N4: =IF(AND(L4="Y",OR(M4<CONFIG!$B$8,M4>CONFIG!$B$9)),"Y","N") | O4: =IF(N4="Y",(H4+K4)*0.8,H4) | P4: =IF(N4="Y",(H4+K4)*0.2,K4) | R4: =DATA!A4 | S4: =DATA!B4 | T4: =CONFIG!$B$5*0.8 | U4: =CONFIG!$B$5*0.2 | V4: =T4+U4 | W4: =DATA!D4 | X4: =DATA!F4 | Y4: =T4*(1+W4) | Z4: =U4*(1+X4) | AA4: =CONFIG!$B$5*CONFIG!$B$6/12 | AB4: =MAX(0,Z4-AA4) | AC4: =IF(OR(MONTH(R4)=3,MONTH(R4)=6,MONTH(R4)=9,MONTH(R4)=12),"Y","N") | AD4: =IF((Y4+AB4)=0,0,AB4/(Y4+AB4)) | AE4: =IF(AND(AC4="Y",OR(AD4<CONFIG!$B$8,AD4>CONFIG!$B$9)),"Y","N") | AF4: =IF(AE4="Y",(Y4+AB4)*0.8,Y4) | AG4: =IF(AE4="Y",(Y4+AB4)*0.2,AB4) | AI4: =DATA!A4 | AJ4: =DATA!B4 | AK4: =CONFIG!$B$5*0.8 | AL4: =CONFIG!$B$5*0.2 | AM4: =AK4+AL4 | AN4: =DATA!E4 | AO4: =DATA!F4 | AP4: =AK4*(1+AN4) | AQ4: =AL4*(1+AO4) | AR4: =CONFIG!$B$5*CONFIG!$B$6/12 | AS4: =MAX(0,AQ4-AR4) | AT4: =IF(OR(MONTH(AI4)=3,MONTH(AI4)=6,MONTH(AI4)=9,MONTH(AI4)=12),"Y","N") | AU4: =IF((AP4+AS4)=0,0,AS4/(AP4+AS4)) | AV4: =IF(AND(AT4="Y",OR(AU4<CONFIG!$B$8,AU4>CONFIG!$B$9)),"Y","N") | AW4: =IF(AV4="Y",(AP4+AS4)*0.8,AP4) | AX4: =IF(AV4="Y",(AP4+AS4)*0.2,AS4)
A5: =DATA!A5 | B5: =DATA!B5 | C5: =O4 | D5: =P4 | E5: =C5+D5 | F5: =DATA!C5 | G5: =DATA!F5 | H5: =C5*(1+F5) | I5: =D5*(1+G5) | J5: =IF(AND(CONFIG!$B$11="Annual",MONTH(A5)=7),(H5+I5)*CONFIG!$B$6/12,J4) | K5: =MAX(0,I5-J5) | L5: =IF(OR(MONTH(A5)=3,MONTH(A5)=6,MONTH(A5)=9,MONTH(A5)=12),"Y","N") | M5: =IF((H5+K5)=0,0,K5/(H5+K5)) | N5: =IF(AND(L5="Y",OR(M5<CONFIG!$B$8,M5>CONFIG!$B$9)),"Y","N") | O5: =IF(N5="Y",(H5+K5)*0.8,H5) | P5: =IF(N5="Y",(H5+K5)*0.2,K5) | R5: =DATA!A5 | S5: =DATA!B5 | T5: =AF4 | U5: =AG4 | V5: =T5+U5 | W5: =DATA!D5 | X5: =DATA!F5 | Y5: =T5*(1+W5) | Z5: =U5*(1+X5) | AA5: =IF(AND(CONFIG!$B$11="Annual",MONTH(R5)=7),(Y5+Z5)*CONFIG!$B$6/12,AA4) | AB5: =MAX(0,Z5-AA5) | AC5: =IF(OR(MONTH(R5)=3,MONTH(R5)=6,MONTH(R5)=9,MONTH(R5)=12),"Y","N") | AD5: =IF((Y5+AB5)=0,0,AB5/(Y5+AB5)) | AE5: =IF(AND(AC5="Y",OR(AD5<CONFIG!$B$8,AD5>CONFIG!$B$9)),"Y","N") | AF5: =IF(AE5="Y",(Y5+AB5)*0.8,Y5) | AG5: =IF(AE5="Y",(Y5+AB5)*0.2,AB5) | AI5: =DATA!A5 | AJ5: =DATA!B5 | AK5: =AW4 | AL5: =AX4 | AM5: =AK5+AL5 | AN5: =DATA!E5 | AO5: =DATA!F5 | AP5: =AK5*(1+AN5) | AQ5: =AL5*(1+AO5) | AR5: =IF(AND(CONFIG!$B$11="Annual",MONTH(AI5)=7),(AP5+AQ5)*CONFIG!$B$6/12,AR4) | AS5: =MAX(0,AQ5-AR5) | AT5: =IF(OR(MONTH(AI5)=3,MONTH(AI5)=6,MONTH(AI5)=9,MONTH(AI5)=12),"Y","N") | AU5: =IF((AP5+AS5)=0,0,AS5/(AP5+AS5)) | AV5: =IF(AND(AT5="Y",OR(AU5<CONFIG!$B$8,AU5>CONFIG!$B$9)),"Y","N") | AW5: =IF(AV5="Y",(AP5+AS5)*0.8,AP5) | AX5: =IF(AV5="Y",(AP5+AS5)*0.2,AS5)
A6: =DATA!A6 | B6: =DATA!B6 | C6: =O5 | D6: =P5 | E6: =C6+D6 | F6: =DATA!C6 | G6: =DATA!F6 | H6: =C6*(1+F6) | I6: =D6*(1+G6) | J6: =IF(AND(CONFIG!$B$11="Annual",MONTH(A6)=7),(H6+I6)*CONFIG!$B$6/12,J5) | K6: =MAX(0,I6-J6) | L6: =IF(OR(MONTH(A6)=3,MONTH(A6)=6,MONTH(A6)=9,MONTH(A6)=12),"Y","N") | M6: =IF((H6+K6)=0,0,K6/(H6+K6)) | N6: =IF(AND(L6="Y",OR(M6<CONFIG!$B$8,M6>CONFIG!$B$9)),"Y","N") | O6: =IF(N6="Y",(H6+K6)*0.8,H6) | P6: =IF(N6="Y",(H6+K6)*0.2,K6) | R6: =DATA!A6 | S6: =DATA!B6 | T6: =AF5 | U6: =AG5 | V6: =T6+U6 | W6: =DATA!D6 | X6: =DATA!F6 | Y6: =T6*(1+W6) | Z6: =U6*(1+X6) | AA6: =IF(AND(CONFIG!$B$11="Annual",MONTH(R6)=7),(Y6+Z6)*CONFIG!$B$6/12,AA5) | AB6: =MAX(0,Z6-AA6) | AC6: =IF(OR(MONTH(R6)=3,MONTH(R6)=6,MONTH(R6)=9,MONTH(R6)=12),"Y","N") | AD6: =IF((Y6+AB6)=0,0,AB6/(Y6+AB6)) | AE6: =IF(AND(AC6="Y",OR(AD6<CONFIG!$B$8,AD6>CONFIG!$B$9)),"Y","N") | AF6: =IF(AE6="Y",(Y6+AB6)*0.8,Y6) | AG6: =IF(AE6="Y",(Y6+AB6)*0.2,AB6) | AI6: =DATA!A6 | AJ6: =DATA!B6 | AK6: =AW5 | AL6: =AX5 | AM6: =AK6+AL6 | AN6: =DATA!E6 | AO6: =DATA!F6 | AP6: =AK6*(1+AN6) | AQ6: =AL6*(1+AO6) | AR6: =IF(AND(CONFIG!$B$11="Annual",MONTH(AI6)=7),(AP6+AQ6)*CONFIG!$B$6/12,AR5) | AS6: =MAX(0,AQ6-AR6) | AT6: =IF(OR(MONTH(AI6)=3,MONTH(AI6)=6,MONTH(AI6)=9,MONTH(AI6)=12),"Y","N") | AU6: =IF((AP6+AS6)=0,0,AS6/(AP6+AS6)) | AV6: =IF(AND(AT6="Y",OR(AU6<CONFIG!$B$8,AU6>CONFIG!$B$9)),"Y","N") | AW6: =IF(AV6="Y",(AP6+AS6)*0.8,AP6) | AX6: =IF(AV6="Y",(AP6+AS6)*0.2,AS6)
A7: =DATA!A7 | B7: =DATA!B7 | C7: =O6 | D7: =P6 | E7: =C7+D7 | F7: =DATA!C7 | G7: =DATA!F7 | H7: =C7*(1+F7) | I7: =D7*(1+G7) | J7: =IF(AND(CONFIG!$B$11="Annual",MONTH(A7)=7),(H7+I7)*CONFIG!$B$6/12,J6) | K7: =MAX(0,I7-J7) | L7: =IF(OR(MONTH(A7)=3,MONTH(A7)=6,MONTH(A7)=9,MONTH(A7)=12),"Y","N") | M7: =IF((H7+K7)=0,0,K7/(H7+K7)) | N7: =IF(AND(L7="Y",OR(M7<CONFIG!$B$8,M7>CONFIG!$B$9)),"Y","N") | O7: =IF(N7="Y",(H7+K7)*0.8,H7) | P7: =IF(N7="Y",(H7+K7)*0.2,K7) | R7: =DATA!A7 | S7: =DATA!B7 | T7: =AF6 | U7: =AG6 | V7: =T7+U7 | W7: =DATA!D7 | X7: =DATA!F7 | Y7: =T7*(1+W7) | Z7: =U7*(1+X7) | AA7: =IF(AND(CONFIG!$B$11="Annual",MONTH(R7)=7),(Y7+Z7)*CONFIG!$B$6/12,AA6) | AB7: =MAX(0,Z7-AA7) | AC7: =IF(OR(MONTH(R7)=3,MONTH(R7)=6,MONTH(R7)=9,MONTH(R7)=12),"Y","N") | AD7: =IF((Y7+AB7)=0,0,AB7/(Y7+AB7)) | AE7: =IF(AND(AC7="Y",OR(AD7<CONFIG!$B$8,AD7>CONFIG!$B$9)),"Y","N") | AF7: =IF(AE7="Y",(Y7+AB7)*0.8,Y7) | AG7: =IF(AE7="Y",(Y7+AB7)*0.2,AB7) | AI7: =DATA!A7 | AJ7: =DATA!B7 | AK7: =AW6 | AL7: =AX6 | AM7: =AK7+AL7 | AN7: =DATA!E7 | AO7: =DATA!F7 | AP7: =AK7*(1+AN7) | AQ7: =AL7*(1+AO7) | AR7: =IF(AND(CONFIG!$B$11="Annual",MONTH(AI7)=7),(AP7+AQ7)*CONFIG!$B$6/12,AR6) | AS7: =MAX(0,AQ7-AR7) | AT7: =IF(OR(MONTH(AI7)=3,MONTH(AI7)=6,MONTH(AI7)=9,MONTH(AI7)=12),"Y","N") | AU7: =IF((AP7+AS7)=0,0,AS7/(AP7+AS7)) | AV7: =IF(AND(AT7="Y",OR(AU7<CONFIG!$B$8,AU7>CONFIG!$B$9)),"Y","N") | AW7: =IF(AV7="Y",(AP7+AS7)*0.8,AP7) | AX7: =IF(AV7="Y",(AP7+AS7)*0.2,AS7)
A8: =DATA!A8 | B8: =DATA!B8 | C8: =O7 | D8: =P7 | E8: =C8+D8 | F8: =DATA!C8 | G8: =DATA!F8 | H8: =C8*(1+F8) | I8: =D8*(1+G8) | J8: =IF(AND(CONFIG!$B$11="Annual",MONTH(A8)=7),(H8+I8)*CONFIG!$B$6/12,J7) | K8: =MAX(0,I8-J8) | L8: =IF(OR(MONTH(A8)=3,MONTH(A8)=6,MONTH(A8)=9,MONTH(A8)=12),"Y","N") | M8: =IF((H8+K8)=0,0,K8/(H8+K8)) | N8: =IF(AND(L8="Y",OR(M8<CONFIG!$B$8,M8>CONFIG!$B$9)),"Y","N") | O8: =IF(N8="Y",(H8+K8)*0.8,H8) | P8: =IF(N8="Y",(H8+K8)*0.2,K8) | R8: =DATA!A8 | S8: =DATA!B8 | T8: =AF7 | U8: =AG7 | V8: =T8+U8 | W8: =DATA!D8 | X8: =DATA!F8 | Y8: =T8*(1+W8) | Z8: =U8*(1+X8) | AA8: =IF(AND(CONFIG!$B$11="Annual",MONTH(R8)=7),(Y8+Z8)*CONFIG!$B$6/12,AA7) | AB8: =MAX(0,Z8-AA8) | AC8: =IF(OR(MONTH(R8)=3,MONTH(R8)=6,MONTH(R8)=9,MONTH(R8)=12),"Y","N") | AD8: =IF((Y8+AB8)=0,0,AB8/(Y8+AB8)) | AE8: =IF(AND(AC8="Y",OR(AD8<CONFIG!$B$8,AD8>CONFIG!$B$9)),"Y","N") | AF8: =IF(AE8="Y",(Y8+AB8)*0.8,Y8) | AG8: =IF(AE8="Y",(Y8+AB8)*0.2,AB8) | AI8: =DATA!A8 | AJ8: =DATA!B8 | AK8: =AW7 | AL8: =AX7 | AM8: =AK8+AL8 | AN8: =DATA!E8 | AO8: =DATA!F8 | AP8: =AK8*(1+AN8) | AQ8: =AL8*(1+AO8) | AR8: =IF(AND(CONFIG!$B$11="Annual",MONTH(AI8)=7),(AP8+AQ8)*CONFIG!$B$6/12,AR7) | AS8: =MAX(0,AQ8-AR8) | AT8: =IF(OR(MONTH(AI8)=3,MONTH(AI8)=6,MONTH(AI8)=9,MONTH(AI8)=12),"Y","N") | AU8: =IF((AP8+AS8)=0,0,AS8/(AP8+AS8)) | AV8: =IF(AND(AT8="Y",OR(AU8<CONFIG!$B$8,AU8>CONFIG!$B$9)),"Y","N") | AW8: =IF(AV8="Y",(AP8+AS8)*0.8,AP8) | AX8: =IF(AV8="Y",(AP8+AS8)*0.2,AS8)
A9: =DATA!A9 | B9: =DATA!B9 | C9: =O8 | D9: =P8 | E9: =C9+D9 | F9: =DATA!C9 | G9: =DATA!F9 | H9: =C9*(1+F9) | I9: =D9*(1+G9) | J9: =IF(AND(CONFIG!$B$11="Annual",MONTH(A9)=7),(H9+I9)*CONFIG!$B$6/12,J8) | K9: =MAX(0,I9-J9) | L9: =IF(OR(MONTH(A9)=3,MONTH(A9)=6,MONTH(A9)=9,MONTH(A9)=12),"Y","N") | M9: =IF((H9+K9)=0,0,K9/(H9+K9)) | N9: =IF(AND(L9="Y",OR(M9<CONFIG!$B$8,M9>CONFIG!$B$9)),"Y","N") | O9: =IF(N9="Y",(H9+K9)*0.8,H9) | P9: =IF(N9="Y",(H9+K9)*0.2,K9) | R9: =DATA!A9 | S9: =DATA!B9 | T9: =AF8 | U9: =AG8 | V9: =T9+U9 | W9: =DATA!D9 | X9: =DATA!F9 | Y9: =T9*(1+W9) | Z9: =U9*(1+X9) | AA9: =IF(AND(CONFIG!$B$11="Annual",MONTH(R9)=7),(Y9+Z9)*CONFIG!$B$6/12,AA8) | AB9: =MAX(0,Z9-AA9) | AC9: =IF(OR(MONTH(R9)=3,MONTH(R9)=6,MONTH(R9)=9,MONTH(R9)=12),"Y","N") | AD9: =IF((Y9+AB9)=0,0,AB9/(Y9+AB9)) | AE9: =IF(AND(AC9="Y",OR(AD9<CONFIG!$B$8,AD9>CONFIG!$B$9)),"Y","N") | AF9: =IF(AE9="Y",(Y9+AB9)*0.8,Y9) | AG9: =IF(AE9="Y",(Y9+AB9)*0.2,AB9) | AI9: =DATA!A9 | AJ9: =DATA!B9 | AK9: =AW8 | AL9: =AX8 | AM9: =AK9+AL9 | AN9: =DATA!E9 | AO9: =DATA!F9 | AP9: =AK9*(1+AN9) | AQ9: =AL9*(1+AO9) | AR9: =IF(AND(CONFIG!$B$11="Annual",MONTH(AI9)=7),(AP9+AQ9)*CONFIG!$B$6/12,AR8) | AS9: =MAX(0,AQ9-AR9) | AT9: =IF(OR(MONTH(AI9)=3,MONTH(AI9)=6,MONTH(AI9)=9,MONTH(AI9)=12),"Y","N") | AU9: =IF((AP9+AS9)=0,0,AS9/(AP9+AS9)) | AV9: =IF(AND(AT9="Y",OR(AU9<CONFIG!$B$8,AU9>CONFIG!$B$9)),"Y","N") | AW9: =IF(AV9="Y",(AP9+AS9)*0.8,AP9) | AX9: =IF(AV9="Y",(AP9+AS9)*0.2,AS9)
A10: =DATA!A10 | B10: =DATA!B10 | C10: =O9 | D10: =P9 | E10: =C10+D10 | F10: =DATA!C10 | G10: =DATA!F10 | H10: =C10*(1+F10) | I10: =D10*(1+G10) | J10: =IF(AND(CONFIG!$B$11="Annual",MONTH(A10)=7),(H10+I10)*CONFIG!$B$6/12,J9) | K10: =MAX(0,I10-J10) | L10: =IF(OR(MONTH(A10)=3,MONTH(A10)=6,MONTH(A10)=9,MONTH(A10)=12),"Y","N") | M10: =IF((H10+K10)=0,0,K10/(H10+K10)) | N10: =IF(AND(L10="Y",OR(M10<CONFIG!$B$8,M10>CONFIG!$B$9)),"Y","N") | O10: =IF(N10="Y",(H10+K10)*0.8,H10) | P10: =IF(N10="Y",(H10+K10)*0.2,K10) | R10: =DATA!A10 | S10: =DATA!B10 | T10: =AF9 | U10: =AG9 | V10: =T10+U10 | W10: =DATA!D10 | X10: =DATA!F10 | Y10: =T10*(1+W10) | Z10: =U10*(1+X10) | AA10: =IF(AND(CONFIG!$B$11="Annual",MONTH(R10)=7),(Y10+Z10)*CONFIG!$B$6/12,AA9) | AB10: =MAX(0,Z10-AA10) | AC10: =IF(OR(MONTH(R10)=3,MONTH(R10)=6,MONTH(R10)=9,MONTH(R10)=12),"Y","N") | AD10: =IF((Y10+AB10)=0,0,AB10/(Y10+AB10)) | AE10: =IF(AND(AC10="Y",OR(AD10<CONFIG!$B$8,AD10>CONFIG!$B$9)),"Y","N") | AF10: =IF(AE10="Y",(Y10+AB10)*0.8,Y10) | AG10: =IF(AE10="Y",(Y10+AB10)*0.2,AB10) | AI10: =DATA!A10 | AJ10: =DATA!B10 | AK10: =AW9 | AL10: =AX9 | AM10: =AK10+AL10 | AN10: =DATA!E10 | AO10: =DATA!F10 | AP10: =AK10*(1+AN10) | AQ10: =AL10*(1+AO10) | AR10: =IF(AND(CONFIG!$B$11="Annual",MONTH(AI10)=7),(AP10+AQ10)*CONFIG!$B$6/12,AR9) | AS10: =MAX(0,AQ10-AR10) | AT10: =IF(OR(MONTH(AI10)=3,MONTH(AI10)=6,MONTH(AI10)=9,MONTH(AI10)=12),"Y","N") | AU10: =IF((AP10+AS10)=0,0,AS10/(AP10+AS10)) | AV10: =IF(AND(AT10="Y",OR(AU10<CONFIG!$B$8,AU10>CONFIG!$B$9)),"Y","N") | AW10: =IF(AV10="Y",(AP10+AS10)*0.8,AP10) | AX10: =IF(AV10="Y",(AP10+AS10)*0.2,AS10)
A11: =DATA!A11 | B11: =DATA!B11 | C11: =O10 | D11: =P10 | E11: =C11+D11 | F11: =DATA!C11 | G11: =DATA!F11 | H11: =C11*(1+F11) | I11: =D11*(1+G11) | J11: =IF(AND(CONFIG!$B$11="Annual",MONTH(A11)=7),(H11+I11)*CONFIG!$B$6/12,J10) | K11: =MAX(0,I11-J11) | L11: =IF(OR(MONTH(A11)=3,MONTH(A11)=6,MONTH(A11)=9,MONTH(A11)=12),"Y","N") | M11: =IF((H11+K11)=0,0,K11/(H11+K11)) | N11: =IF(AND(L11="Y",OR(M11<CONFIG!$B$8,M11>CONFIG!$B$9)),"Y","N") | O11: =IF(N11="Y",(H11+K11)*0.8,H11) | P11: =IF(N11="Y",(H11+K11)*0.2,K11) | R11: =DATA!A11 | S11: =DATA!B11 | T11: =AF10 | U11: =AG10 | V11: =T11+U11 | W11: =DATA!D11 | X11: =DATA!F11 | Y11: =T11*(1+W11) | Z11: =U11*(1+X11) | AA11: =IF(AND(CONFIG!$B$11="Annual",MONTH(R11)=7),(Y11+Z11)*CONFIG!$B$6/12,AA10) | AB11: =MAX(0,Z11-AA11) | AC11: =IF(OR(MONTH(R11)=3,MONTH(R11)=6,MONTH(R11)=9,MONTH(R11)=12),"Y","N") | AD11: =IF((Y11+AB11)=0,0,AB11/(Y11+AB11)) | AE11: =IF(AND(AC11="Y",OR(AD11<CONFIG!$B$8,AD11>CONFIG!$B$9)),"Y","N") | AF11: =IF(AE11="Y",(Y11+AB11)*0.8,Y11) | AG11: =IF(AE11="Y",(Y11+AB11)*0.2,AB11) | AI11: =DATA!A11 | AJ11: =DATA!B11 | AK11: =AW10 | AL11: =AX10 | AM11: =AK11+AL11 | AN11: =DATA!E11 | AO11: =DATA!F11 | AP11: =AK11*(1+AN11) | AQ11: =AL11*(1+AO11) | AR11: =IF(AND(CONFIG!$B$11="Annual",MONTH(AI11)=7),(AP11+AQ11)*CONFIG!$B$6/12,AR10) | AS11: =MAX(0,AQ11-AR11) | AT11: =IF(OR(MONTH(AI11)=3,MONTH(AI11)=6,MONTH(AI11)=9,MONTH(AI11)=12),"Y","N") | AU11: =IF((AP11+AS11)=0,0,AS11/(AP11+AS11)) | AV11: =IF(AND(AT11="Y",OR(AU11<CONFIG!$B$8,AU11>CONFIG!$B$9)),"Y","N") | AW11: =IF(AV11="Y",(AP11+AS11)*0.8,AP11) | AX11: =IF(AV11="Y",(AP11+AS11)*0.2,AS11)
A12: =DATA!A12 | B12: =DATA!B12 | C12: =O11 | D12: =P11 | E12: =C12+D12 | F12: =DATA!C12 | G12: =DATA!F12 | H12: =C12*(1+F12) | I12: =D12*(1+G12) | J12: =IF(AND(CONFIG!$B$11="Annual",MONTH(A12)=7),(H12+I12)*CONFIG!$B$6/12,J11) | K12: =MAX(0,I12-J12) | L12: =IF(OR(MONTH(A12)=3,MONTH(A12)=6,MONTH(A12)=9,MONTH(A12)=12),"Y","N") | M12: =IF((H12+K12)=0,0,K12/(H12+K12)) | N12: =IF(AND(L12="Y",OR(M12<CONFIG!$B$8,M12>CONFIG!$B$9)),"Y","N") | O12: =IF(N12="Y",(H12+K12)*0.8,H12) | P12: =IF(N12="Y",(H12+K12)*0.2,K12) | R12: =DATA!A12 | S12: =DATA!B12 | T12: =AF11 | U12: =AG11 | V12: =T12+U12 | W12: =DATA!D12 | X12: =DATA!F12 | Y12: =T12*(1+W12) | Z12: =U12*(1+X12) | AA12: =IF(AND(CONFIG!$B$11="Annual",MONTH(R12)=7),(Y12+Z12)*CONFIG!$B$6/12,AA11) | AB12: =MAX(0,Z12-AA12) | AC12: =IF(OR(MONTH(R12)=3,MONTH(R12)=6,MONTH(R12)=9,MONTH(R12)=12),"Y","N") | AD12: =IF((Y12+AB12)=0,0,AB12/(Y12+AB12)) | AE12: =IF(AND(AC12="Y",OR(AD12<CONFIG!$B$8,AD12>CONFIG!$B$9)),"Y","N") | AF12: =IF(AE12="Y",(Y12+AB12)*0.8,Y12) | AG12: =IF(AE12="Y",(Y12+AB12)*0.2,AB12) | AI12: =DATA!A12 | AJ12: =DATA!B12 | AK12: =AW11 | AL12: =AX11 | AM12: =AK12+AL12 | AN12: =DATA!E12 | AO12: =DATA!F12 | AP12: =AK12*(1+AN12) | AQ12: =AL12*(1+AO12) | AR12: =IF(AND(CONFIG!$B$11="Annual",MONTH(AI12)=7),(AP12+AQ12)*CONFIG!$B$6/12,AR11) | AS12: =MAX(0,AQ12-AR12) | AT12: =IF(OR(MONTH(AI12)=3,MONTH(AI12)=6,MONTH(AI12)=9,MONTH(AI12)=12),"Y","N") | AU12: =IF((AP12+AS12)=0,0,AS12/(AP12+AS12)) | AV12: =IF(AND(AT12="Y",OR(AU12<CONFIG!$B$8,AU12>CONFIG!$B$9)),"Y","N") | AW12: =IF(AV12="Y",(AP12+AS12)*0.8,AP12) | AX12: =IF(AV12="Y",(AP12+AS12)*0.2,AS12)
A13: =DATA!A13 | B13: =DATA!B13 | C13: =O12 | D13: =P12 | E13: =C13+D13 | F13: =DATA!C13 | G13: =DATA!F13 | H13: =C13*(1+F13) | I13: =D13*(1+G13) | J13: =IF(AND(CONFIG!$B$11="Annual",MONTH(A13)=7),(H13+I13)*CONFIG!$B$6/12,J12) | K13: =MAX(0,I13-J13) | L13: =IF(OR(MONTH(A13)=3,MONTH(A13)=6,MONTH(A13)=9,MONTH(A13)=12),"Y","N") | M13: =IF((H13+K13)=0,0,K13/(H13+K13)) | N13: =IF(AND(L13="Y",OR(M13<CONFIG!$B$8,M13>CONFIG!$B$9)),"Y","N") | O13: =IF(N13="Y",(H13+K13)*0.8,H13) | P13: =IF(N13="Y",(H13+K13)*0.2,K13) | R13: =DATA!A13 | S13: =DATA!B13 | T13: =AF12 | U13: =AG12 | V13: =T13+U13 | W13: =DATA!D13 | X13: =DATA!F13 | Y13: =T13*(1+W13) | Z13: =U13*(1+X13) | AA13: =IF(AND(CONFIG!$B$11="Annual",MONTH(R13)=7),(Y13+Z13)*CONFIG!$B$6/12,AA12) | AB13: =MAX(0,Z13-AA13) | AC13: =IF(OR(MONTH(R13)=3,MONTH(R13)=6,MONTH(R13)=9,MONTH(R13)=12),"Y","N") | AD13: =IF((Y13+AB13)=0,0,AB13/(Y13+AB13)) | AE13: =IF(AND(AC13="Y",OR(AD13<CONFIG!$B$8,AD13>CONFIG!$B$9)),"Y","N") | AF13: =IF(AE13="Y",(Y13+AB13)*0.8,Y13) | AG13: =IF(AE13="Y",(Y13+AB13)*0.2,AB13) | AI13: =DATA!A13 | AJ13: =DATA!B13 | AK13: =AW12 | AL13: =AX12 | AM13: =AK13+AL13 | AN13: =DATA!E13 | AO13: =DATA!F13 | AP13: =AK13*(1+AN13) | AQ13: =AL13*(1+AO13) | AR13: =IF(AND(CONFIG!$B$11="Annual",MONTH(AI13)=7),(AP13+AQ13)*CONFIG!$B$6/12,AR12) | AS13: =MAX(0,AQ13-AR13) | AT13: =IF(OR(MONTH(AI13)=3,MONTH(AI13)=6,MONTH(AI13)=9,MONTH(AI13)=12),"Y","N") | AU13: =IF((AP13+AS13)=0,0,AS13/(AP13+AS13)) | AV13: =IF(AND(AT13="Y",OR(AU13<CONFIG!$B$8,AU13>CONFIG!$B$9)),"Y","N") | AW13: =IF(AV13="Y",(AP13+AS13)*0.8,AP13) | AX13: =IF(AV13="Y",(AP13+AS13)*0.2,AS13)
A14: =DATA!A14 | B14: =DATA!B14 | C14: =O13 | D14: =P13 | E14: =C14+D14 | F14: =DATA!C14 | G14: =DATA!F14 | H14: =C14*(1+F14) | I14: =D14*(1+G14) | J14: =IF(AND(CONFIG!$B$11="Annual",MONTH(A14)=7),(H14+I14)*CONFIG!$B$6/12,J13) | K14: =MAX(0,I14-J14) | L14: =IF(OR(MONTH(A14)=3,MONTH(A14)=6,MONTH(A14)=9,MONTH(A14)=12),"Y","N") | M14: =IF((H14+K14)=0,0,K14/(H14+K14)) | N14: =IF(AND(L14="Y",OR(M14<CONFIG!$B$8,M14>CONFIG!$B$9)),"Y","N") | O14: =IF(N14="Y",(H14+K14)*0.8,H14) | P14: =IF(N14="Y",(H14+K14)*0.2,K14) | R14: =DATA!A14 | S14: =DATA!B14 | T14: =AF13 | U14: =AG13 | V14: =T14+U14 | W14: =DATA!D14 | X14: =DATA!F14 | Y14: =T14*(1+W14) | Z14: =U14*(1+X14) | AA14: =IF(AND(CONFIG!$B$11="Annual",MONTH(R14)=7),(Y14+Z14)*CONFIG!$B$6/12,AA13) | AB14: =MAX(0,Z14-AA14) | AC14: =IF(OR(MONTH(R14)=3,MONTH(R14)=6,MONTH(R14)=9,MONTH(R14)=12),"Y","N") | AD14: =IF((Y14+AB14)=0,0,AB14/(Y14+AB14)) | AE14: =IF(AND(AC14="Y",OR(AD14<CONFIG!$B$8,AD14>CONFIG!$B$9)),"Y","N") | AF14: =IF(AE14="Y",(Y14+AB14)*0.8,Y14) | AG14: =IF(AE14="Y",(Y14+AB14)*0.2,AB14) | AI14: =DATA!A14 | AJ14: =DATA!B14 | AK14: =AW13 | AL14: =AX13 | AM14: =AK14+AL14 | AN14: =DATA!E14 | AO14: =DATA!F14 | AP14: =AK14*(1+AN14) | AQ14: =AL14*(1+AO14) | AR14: =IF(AND(CONFIG!$B$11="Annual",MONTH(AI14)=7),(AP14+AQ14)*CONFIG!$B$6/12,AR13) | AS14: =MAX(0,AQ14-AR14) | AT14: =IF(OR(MONTH(AI14)=3,MONTH(AI14)=6,MONTH(AI14)=9,MONTH(AI14)=12),"Y","N") | AU14: =IF((AP14+AS14)=0,0,AS14/(AP14+AS14)) | AV14: =IF(AND(AT14="Y",OR(AU14<CONFIG!$B$8,AU14>CONFIG!$B$9)),"Y","N") | AW14: =IF(AV14="Y",(AP14+AS14)*0.8,AP14) | AX14: =IF(AV14="Y",(AP14+AS14)*0.2,AS14)
A15: =DATA!A15 | B15: =DATA!B15 | C15: =O14 | D15: =P14 | E15: =C15+D15 | F15: =DATA!C15 | G15: =DATA!F15 | H15: =C15*(1+F15) | I15: =D15*(1+G15) | J15: =IF(AND(CONFIG!$B$11="Annual",MONTH(A15)=7),(H15+I15)*CONFIG!$B$6/12,J14) | K15: =MAX(0,I15-J15) | L15: =IF(OR(MONTH(A15)=3,MONTH(A15)=6,MONTH(A15)=9,MONTH(A15)=12),"Y","N") | M15: =IF((H15+K15)=0,0,K15/(H15+K15)) | N15: =IF(AND(L15="Y",OR(M15<CONFIG!$B$8,M15>CONFIG!$B$9)),"Y","N") | O15: =IF(N15="Y",(H15+K15)*0.8,H15) | P15: =IF(N15="Y",(H15+K15)*0.2,K15) | R15: =DATA!A15 | S15: =DATA!B15 | T15: =AF14 | U15: =AG14 | V15: =T15+U15 | W15: =DATA!D15 | X15: =DATA!F15 | Y15: =T15*(1+W15) | Z15: =U15*(1+X15) | AA15: =IF(AND(CONFIG!$B$11="Annual",MONTH(R15)=7),(Y15+Z15)*CONFIG!$B$6/12,AA14) | AB15: =MAX(0,Z15-AA15) | AC15: =IF(OR(MONTH(R15)=3,MONTH(R15)=6,MONTH(R15)=9,MONTH(R15)=12),"Y","N") | AD15: =IF((Y15+AB15)=0,0,AB15/(Y15+AB15)) | AE15: =IF(AND(AC15="Y",OR(AD15<CONFIG!$B$8,AD15>CONFIG!$B$9)),"Y","N") | AF15: =IF(AE15="Y",(Y15+AB15)*0.8,Y15) | AG15: =IF(AE15="Y",(Y15+AB15)*0.2,AB15) | AI15: =DATA!A15 | AJ15: =DATA!B15 | AK15: =AW14 | AL15: =AX14 | AM15: =AK15+AL15 | AN15: =DATA!E15 | AO15: =DATA!F15 | AP15: =AK15*(1+AN15) | AQ15: =AL15*(1+AO15) | AR15: =IF(AND(CONFIG!$B$11="Annual",MONTH(AI15)=7),(AP15+AQ15)*CONFIG!$B$6/12,AR14) | AS15: =MAX(0,AQ15-AR15) | AT15: =IF(OR(MONTH(AI15)=3,MONTH(AI15)=6,MONTH(AI15)=9,MONTH(AI15)=12),"Y","N") | AU15: =IF((AP15+AS15)=0,0,AS15/(AP15+AS15)) | AV15: =IF(AND(AT15="Y",OR(AU15<CONFIG!$B$8,AU15>CONFIG!$B$9)),"Y","N") | AW15: =IF(AV15="Y",(AP15+AS15)*0.8,AP15) | AX15: =IF(AV15="Y",(AP15+AS15)*0.2,AS15)
A16: =DATA!A16 | B16: =DATA!B16 | C16: =O15 | D16: =P15 | E16: =C16+D16 | F16: =DATA!C16 | G16: =DATA!F16 | H16: =C16*(1+F16) | I16: =D16*(1+G16) | J16: =IF(AND(CONFIG!$B$11="Annual",MONTH(A16)=7),(H16+I16)*CONFIG!$B$6/12,J15) | K16: =MAX(0,I16-J16) | L16: =IF(OR(MONTH(A16)=3,MONTH(A16)=6,MONTH(A16)=9,MONTH(A16)=12),"Y","N") | M16: =IF((H16+K16)=0,0,K16/(H16+K16)) | N16: =IF(AND(L16="Y",OR(M16<CONFIG!$B$8,M16>CONFIG!$B$9)),"Y","N") | O16: =IF(N16="Y",(H16+K16)*0.8,H16) | P16: =IF(N16="Y",(H16+K16)*0.2,K16) | R16: =DATA!A16 | S16: =DATA!B16 | T16: =AF15 | U16: =AG15 | V16: =T16+U16 | W16: =DATA!D16 | X16: =DATA!F16 | Y16: =T16*(1+W16) | Z16: =U16*(1+X16) | AA16: =IF(AND(CONFIG!$B$11="Annual",MONTH(R16)=7),(Y16+Z16)*CONFIG!$B$6/12,AA15) | AB16: =MAX(0,Z16-AA16) | AC16: =IF(OR(MONTH(R16)=3,MONTH(R16)=6,MONTH(R16)=9,MONTH(R16)=12),"Y","N") | AD16: =IF((Y16+AB16)=0,0,AB16/(Y16+AB16)) | AE16: =IF(AND(AC16="Y",OR(AD16<CONFIG!$B$8,AD16>CONFIG!$B$9)),"Y","N") | AF16: =IF(AE16="Y",(Y16+AB16)*0.8,Y16) | AG16: =IF(AE16="Y",(Y16+AB16)*0.2,AB16) | AI16: =DATA!A16 | AJ16: =DATA!B16 | AK16: =AW15 | AL16: =AX15 | AM16: =AK16+AL16 | AN16: =DATA!E16 | AO16: =DATA!F16 | AP16: =AK16*(1+AN16) | AQ16: =AL16*(1+AO16) | AR16: =IF(AND(CONFIG!$B$11="Annual",MONTH(AI16)=7),(AP16+AQ16)*CONFIG!$B$6/12,AR15) | AS16: =MAX(0,AQ16-AR16) | AT16: =IF(OR(MONTH(AI16)=3,MONTH(AI16)=6,MONTH(AI16)=9,MONTH(AI16)=12),"Y","N") | AU16: =IF((AP16+AS16)=0,0,AS16/(AP16+AS16)) | AV16: =IF(AND(AT16="Y",OR(AU16<CONFIG!$B$8,AU16>CONFIG!$B$9)),"Y","N") | AW16: =IF(AV16="Y",(AP16+AS16)*0.8,AP16) | AX16: =IF(AV16="Y",(AP16+AS16)*0.2,AS16)
... A283: =DATA!A283 | B283: =DATA!B283 | C283: =O282 | D283: =P282 | E283: =C283+D283 | F283: =DATA!C283 | G283: =DATA!F283 | H283: =C283*(1+F283) | I283: =D283*(1+G283) | J283: =IF(AND(CONFIG!$B$11="Annual",MONTH(A283)=7),(H283+I283)*CONFIG!$B$6/12,J282) | K283: =MAX(0,I283-J283) | L283: =IF(OR(MONTH(A283)=3,MONTH(A283)=6,MONTH(A283)=9,MONTH(A283)=12),"Y","N") | M283: =IF((H283+K283)=0,0,K283/(H283+K283)) | N283: =IF(AND(L283="Y",OR(M283<CONFIG!$B$8,M283>CONFIG!$B$9)),"Y","N") | O283: =IF(N283="Y",(H283+K283)*0.8,H283) | P283: =IF(N283="Y",(H283+K283)*0.2,K283) | R283: =DATA!A283 | S283: =DATA!B283 | T283: =AF282 | U283: =AG282 | V283: =T283+U283 | W283: =DATA!D283 | X283: =DATA!F283 | Y283: =T283*(1+W283) | Z283: =U283*(1+X283) | AA283: =IF(AND(CONFIG!$B$11="Annual",MONTH(R283)=7),(Y283+Z283)*CONFIG!$B$6/12,AA282) | AB283: =MAX(0,Z283-AA283) | AC283: =IF(OR(MONTH(R283)=3,MONTH(R283)=6,MONTH(R283)=9,MONTH(R283)=12),"Y","N") | AD283: =IF((Y283+AB283)=0,0,AB283/(Y283+AB283)) | AE283: =IF(AND(AC283="Y",OR(AD283<CONFIG!$B$8,AD283>CONFIG!$B$9)),"Y","N") | AF283: =IF(AE283="Y",(Y283+AB283)*0.8,Y283) | AG283: =IF(AE283="Y",(Y283+AB283)*0.2,AB283) | AI283: =DATA!A283 | AJ283: =DATA!B283 | AK283: =AW282 | AL283: =AX282 | AM283: =AK283+AL283 | AN283: =DATA!E283 | AO283: =DATA!F283 | AP283: =AK283*(1+AN283) | AQ283: =AL283*(1+AO283) | AR283: =IF(AND(CONFIG!$B$11="Annual",MONTH(AI283)=7),(AP283+AQ283)*CONFIG!$B$6/12,AR282) | AS283: =MAX(0,AQ283-AR283) | AT283: =IF(OR(MONTH(AI283)=3,MONTH(AI283)=6,MONTH(AI283)=9,MONTH(AI283)=12),"Y","N") | AU283: =IF((AP283+AS283)=0,0,AS283/(AP283+AS283)) | AV283: =IF(AND(AT283="Y",OR(AU283<CONFIG!$B$8,AU283>CONFIG!$B$9)),"Y","N") | AW283: =IF(AV283="Y",(AP283+AS283)*0.8,AP283) | AX283: =IF(AV283="Y",(AP283+AS283)*0.2,AS283)

Sheet COMPARISON
A1: Benchmark: 80% Option / 20% Cash — No Rebalancing, Pro-Rata Drawdown
A2: Benchmark: 80% Growth / 20% Cash | O2: Benchmark: 80% Balanced / 20% Cash | AC2: Benchmark: 80% Conservative / 20% Cash
A3: Date | B3: Month # | C3: Growth Open | D3: Cash Open | E3: Total Open | F3: Growth Return | G3: Cash Return | H3: Growth Post-Return | I3: Cash Post-Return | J3: Total Pre-Drawdown | K3: Monthly Payment | L3: Growth Close | M3: Cash Close | O3: Date | P3: Month # | Q3: Balanced Open | R3: Cash Open | S3: Total Open | T3: Balanced Return | U3: Cash Return | V3: Balanced Post-Return | W3: Cash Post-Return | X3: Total Pre-Drawdown | Y3: Monthly Payment | Z3: Balanced Close | AA3: Cash Close | AC3: Date | AD3: Month # | AE3: Conservative Open | AF3: Cash Open | AG3: Total Open | AH3: Conservative Return | AI3: Cash Return | AJ3: Conservative Post-Return | AK3: Cash Post-Return | AL3: Total Pre-Drawdown | AM3: Monthly Payment | AN3: Conservative Close | AO3: Cash Close
A4: =DATA!A4 | B4: =DATA!B4 | C4: =CONFIG!$B$5*0.8 | D4: =CONFIG!$B$5*0.2 | E4: =C4+D4 | F4: =DATA!C4 | G4: =DATA!G4 | H4: =C4*(1+F4) | I4: =D4*(1+G4) | J4: =H4+I4 | K4: =CONFIG!$B$5*CONFIG!$B$6/12 | L4: =IF(J4=0,0,H4-K4*H4/J4) | M4: =IF(J4=0,0,I4-K4*I4/J4) | O4: =DATA!A4 | P4: =DATA!B4 | Q4: =CONFIG!$B$5*0.8 | R4: =CONFIG!$B$5*0.2 | S4: =Q4+R4 | T4: =DATA!D4 | U4: =DATA!G4 | V4: =Q4*(1+T4) | W4: =R4*(1+U4) | X4: =V4+W4 | Y4: =CONFIG!$B$5*CONFIG!$B$6/12 | Z4: =IF(X4=0,0,V4-Y4*V4/X4) | AA4: =IF(X4=0,0,W4-Y4*W4/X4) | AC4: =DATA!A4 | AD4: =DATA!B4 | AE4: =CONFIG!$B$5*0.8 | AF4: =CONFIG!$B$5*0.2 | AG4: =AE4+AF4 | AH4: =DATA!E4 | AI4: =DATA!G4 | AJ4: =AE4*(1+AH4) | AK4: =AF4*(1+AI4) | AL4: =AJ4+AK4 | AM4: =CONFIG!$B$5*CONFIG!$B$6/12 | AN4: =IF(AL4=0,0,AJ4-AM4*AJ4/AL4) | AO4: =IF(AL4=0,0,AK4-AM4*AK4/AL4)
A5: =DATA!A5 | B5: =DATA!B5 | C5: =L4 | D5: =M4 | E5: =C5+D5 | F5: =DATA!C5 | G5: =DATA!G5 | H5: =C5*(1+F5) | I5: =D5*(1+G5) | J5: =H5+I5 | K5: =IF(AND(CONFIG!$B$11="Annual",MONTH(A5)=7),J5*CONFIG!$B$6/12,K4) | L5: =IF(J5=0,0,H5-K5*H5/J5) | M5: =IF(J5=0,0,I5-K5*I5/J5) | O5: =DATA!A5 | P5: =DATA!B5 | Q5: =Z4 | R5: =AA4 | S5: =Q5+R5 | T5: =DATA!D5 | U5: =DATA!G5 | V5: =Q5*(1+T5) | W5: =R5*(1+U5) | X5: =V5+W5 | Y5: =IF(AND(CONFIG!$B$11="Annual",MONTH(O5)=7),X5*CONFIG!$B$6/12,Y4) | Z5: =IF(X5=0,0,V5-Y5*V5/X5) | AA5: =IF(X5=0,0,W5-Y5*W5/X5) | AC5: =DATA!A5 | AD5: =DATA!B5 | AE5: =AN4 | AF5: =AO4 | AG5: =AE5+AF5 | AH5: =DATA!E5 | AI5: =DATA!G5 | AJ5: =AE5*(1+AH5) | AK5: =AF5*(1+AI5) | AL5: =AJ5+AK5 | AM5: =IF(AND(CONFIG!$B$11="Annual",MONTH(AC5)=7),AL5*CONFIG!$B$6/12,AM4) | AN5: =IF(AL5=0,0,AJ5-AM5*AJ5/AL5) | AO5: =IF(AL5=0,0,AK5-AM5*AK5/AL5)
A6: =DATA!A6 | B6: =DATA!B6 | C6: =L5 | D6: =M5 | E6: =C6+D6 | F6: =DATA!C6 | G6: =DATA!G6 | H6: =C6*(1+F6) | I6: =D6*(1+G6) | J6: =H6+I6 | K6: =IF(AND(CONFIG!$B$11="Annual",MONTH(A6)=7),J6*CONFIG!$B$6/12,K5) | L6: =IF(J6=0,0,H6-K6*H6/J6) | M6: =IF(J6=0,0,I6-K6*I6/J6) | O6: =DATA!A6 | P6: =DATA!B6 | Q6: =Z5 | R6: =AA5 | S6: =Q6+R6 | T6: =DATA!D6 | U6: =DATA!G6 | V6: =Q6*(1+T6) | W6: =R6*(1+U6) | X6: =V6+W6 | Y6: =IF(AND(CONFIG!$B$11="Annual",MONTH(O6)=7),X6*CONFIG!$B$6/12,Y5) | Z6: =IF(X6=0,0,V6-Y6*V6/X6) | AA6: =IF(X6=0,0,W6-Y6*W6/X6) | AC6: =DATA!A6 | AD6: =DATA!B6 | AE6: =AN5 | AF6: =AO5 | AG6: =AE6+AF6 | AH6: =DATA!E6 | AI6: =DATA!G6 | AJ6: =AE6*(1+AH6) | AK6: =AF6*(1+AI6) | AL6: =AJ6+AK6 | AM6: =IF(AND(CONFIG!$B$11="Annual",MONTH(AC6)=7),AL6*CONFIG!$B$6/12,AM5) | AN6: =IF(AL6=0,0,AJ6-AM6*AJ6/AL6) | AO6: =IF(AL6=0,0,AK6-AM6*AK6/AL6)
A7: =DATA!A7 | B7: =DATA!B7 | C7: =L6 | D7: =M6 | E7: =C7+D7 | F7: =DATA!C7 | G7: =DATA!G7 | H7: =C7*(1+F7) | I7: =D7*(1+G7) | J7: =H7+I7 | K7: =IF(AND(CONFIG!$B$11="Annual",MONTH(A7)=7),J7*CONFIG!$B$6/12,K6) | L7: =IF(J7=0,0,H7-K7*H7/J7) | M7: =IF(J7=0,0,I7-K7*I7/J7) | O7: =DATA!A7 | P7: =DATA!B7 | Q7: =Z6 | R7: =AA6 | S7: =Q7+R7 | T7: =DATA!D7 | U7: =DATA!G7 | V7: =Q7*(1+T7) | W7: =R7*(1+U7) | X7: =V7+W7 | Y7: =IF(AND(CONFIG!$B$11="Annual",MONTH(O7)=7),X7*CONFIG!$B$6/12,Y6) | Z7: =IF(X7=0,0,V7-Y7*V7/X7) | AA7: =IF(X7=0,0,W7-Y7*W7/X7) | AC7: =DATA!A7 | AD7: =DATA!B7 | AE7: =AN6 | AF7: =AO6 | AG7: =AE7+AF7 | AH7: =DATA!E7 | AI7: =DATA!G7 | AJ7: =AE7*(1+AH7) | AK7: =AF7*(1+AI7) | AL7: =AJ7+AK7 | AM7: =IF(AND(CONFIG!$B$11="Annual",MONTH(AC7)=7),AL7*CONFIG!$B$6/12,AM6) | AN7: =IF(AL7=0,0,AJ7-AM7*AJ7/AL7) | AO7: =IF(AL7=0,0,AK7-AM7*AK7/AL7)
A8: =DATA!A8 | B8: =DATA!B8 | C8: =L7 | D8: =M7 | E8: =C8+D8 | F8: =DATA!C8 | G8: =DATA!G8 | H8: =C8*(1+F8) | I8: =D8*(1+G8) | J8: =H8+I8 | K8: =IF(AND(CONFIG!$B$11="Annual",MONTH(A8)=7),J8*CONFIG!$B$6/12,K7) | L8: =IF(J8=0,0,H8-K8*H8/J8) | M8: =IF(J8=0,0,I8-K8*I8/J8) | O8: =DATA!A8 | P8: =DATA!B8 | Q8: =Z7 | R8: =AA7 | S8: =Q8+R8 | T8: =DATA!D8 | U8: =DATA!G8 | V8: =Q8*(1+T8) | W8: =R8*(1+U8) | X8: =V8+W8 | Y8: =IF(AND(CONFIG!$B$11="Annual",MONTH(O8)=7),X8*CONFIG!$B$6/12,Y7) | Z8: =IF(X8=0,0,V8-Y8*V8/X8) | AA8: =IF(X8=0,0,W8-Y8*W8/X8) | AC8: =DATA!A8 | AD8: =DATA!B8 | AE8: =AN7 | AF8: =AO7 | AG8: =AE8+AF8 | AH8: =DATA!E8 | AI8: =DATA!G8 | AJ8: =AE8*(1+AH8) | AK8: =AF8*(1+AI8) | AL8: =AJ8+AK8 | AM8: =IF(AND(CONFIG!$B$11="Annual",MONTH(AC8)=7),AL8*CONFIG!$B$6/12,AM7) | AN8: =IF(AL8=0,0,AJ8-AM8*AJ8/AL8) | AO8: =IF(AL8=0,0,AK8-AM8*AK8/AL8)
A9: =DATA!A9 | B9: =DATA!B9 | C9: =L8 | D9: =M8 | E9: =C9+D9 | F9: =DATA!C9 | G9: =DATA!G9 | H9: =C9*(1+F9) | I9: =D9*(1+G9) | J9: =H9+I9 | K9: =IF(AND(CONFIG!$B$11="Annual",MONTH(A9)=7),J9*CONFIG!$B$6/12,K8) | L9: =IF(J9=0,0,H9-K9*H9/J9) | M9: =IF(J9=0,0,I9-K9*I9/J9) | O9: =DATA!A9 | P9: =DATA!B9 | Q9: =Z8 | R9: =AA8 | S9: =Q9+R9 | T9: =DATA!D9 | U9: =DATA!G9 | V9: =Q9*(1+T9) | W9: =R9*(1+U9) | X9: =V9+W9 | Y9: =IF(AND(CONFIG!$B$11="Annual",MONTH(O9)=7),X9*CONFIG!$B$6/12,Y8) | Z9: =IF(X9=0,0,V9-Y9*V9/X9) | AA9: =IF(X9=0,0,W9-Y9*W9/X9) | AC9: =DATA!A9 | AD9: =DATA!B9 | AE9: =AN8 | AF9: =AO8 | AG9: =AE9+AF9 | AH9: =DATA!E9 | AI9: =DATA!G9 | AJ9: =AE9*(1+AH9) | AK9: =AF9*(1+AI9) | AL9: =AJ9+AK9 | AM9: =IF(AND(CONFIG!$B$11="Annual",MONTH(AC9)=7),AL9*CONFIG!$B$6/12,AM8) | AN9: =IF(AL9=0,0,AJ9-AM9*AJ9/AL9) | AO9: =IF(AL9=0,0,AK9-AM9*AK9/AL9)
A10: =DATA!A10 | B10: =DATA!B10 | C10: =L9 | D10: =M9 | E10: =C10+D10 | F10: =DATA!C10 | G10: =DATA!G10 | H10: =C10*(1+F10) | I10: =D10*(1+G10) | J10: =H10+I10 | K10: =IF(AND(CONFIG!$B$11="Annual",MONTH(A10)=7),J10*CONFIG!$B$6/12,K9) | L10: =IF(J10=0,0,H10-K10*H10/J10) | M10: =IF(J10=0,0,I10-K10*I10/J10) | O10: =DATA!A10 | P10: =DATA!B10 | Q10: =Z9 | R10: =AA9 | S10: =Q10+R10 | T10: =DATA!D10 | U10: =DATA!G10 | V10: =Q10*(1+T10) | W10: =R10*(1+U10) | X10: =V10+W10 | Y10: =IF(AND(CONFIG!$B$11="Annual",MONTH(O10)=7),X10*CONFIG!$B$6/12,Y9) | Z10: =IF(X10=0,0,V10-Y10*V10/X10) | AA10: =IF(X10=0,0,W10-Y10*W10/X10) | AC10: =DATA!A10 | AD10: =DATA!B10 | AE10: =AN9 | AF10: =AO9 | AG10: =AE10+AF10 | AH10: =DATA!E10 | AI10: =DATA!G10 | AJ10: =AE10*(1+AH10) | AK10: =AF10*(1+AI10) | AL10: =AJ10+AK10 | AM10: =IF(AND(CONFIG!$B$11="Annual",MONTH(AC10)=7),AL10*CONFIG!$B$6/12,AM9) | AN10: =IF(AL10=0,0,AJ10-AM10*AJ10/AL10) | AO10: =IF(AL10=0,0,AK10-AM10*AK10/AL10)
A11: =DATA!A11 | B11: =DATA!B11 | C11: =L10 | D11: =M10 | E11: =C11+D11 | F11: =DATA!C11 | G11: =DATA!G11 | H11: =C11*(1+F11) | I11: =D11*(1+G11) | J11: =H11+I11 | K11: =IF(AND(CONFIG!$B$11="Annual",MONTH(A11)=7),J11*CONFIG!$B$6/12,K10) | L11: =IF(J11=0,0,H11-K11*H11/J11) | M11: =IF(J11=0,0,I11-K11*I11/J11) | O11: =DATA!A11 | P11: =DATA!B11 | Q11: =Z10 | R11: =AA10 | S11: =Q11+R11 | T11: =DATA!D11 | U11: =DATA!G11 | V11: =Q11*(1+T11) | W11: =R11*(1+U11) | X11: =V11+W11 | Y11: =IF(AND(CONFIG!$B$11="Annual",MONTH(O11)=7),X11*CONFIG!$B$6/12,Y10) | Z11: =IF(X11=0,0,V11-Y11*V11/X11) | AA11: =IF(X11=0,0,W11-Y11*W11/X11) | AC11: =DATA!A11 | AD11: =DATA!B11 | AE11: =AN10 | AF11: =AO10 | AG11: =AE11+AF11 | AH11: =DATA!E11 | AI11: =DATA!G11 | AJ11: =AE11*(1+AH11) | AK11: =AF11*(1+AI11) | AL11: =AJ11+AK11 | AM11: =IF(AND(CONFIG!$B$11="Annual",MONTH(AC11)=7),AL11*CONFIG!$B$6/12,AM10) | AN11: =IF(AL11=0,0,AJ11-AM11*AJ11/AL11) | AO11: =IF(AL11=0,0,AK11-AM11*AK11/AL11)
A12: =DATA!A12 | B12: =DATA!B12 | C12: =L11 | D12: =M11 | E12: =C12+D12 | F12: =DATA!C12 | G12: =DATA!G12 | H12: =C12*(1+F12) | I12: =D12*(1+G12) | J12: =H12+I12 | K12: =IF(AND(CONFIG!$B$11="Annual",MONTH(A12)=7),J12*CONFIG!$B$6/12,K11) | L12: =IF(J12=0,0,H12-K12*H12/J12) | M12: =IF(J12=0,0,I12-K12*I12/J12) | O12: =DATA!A12 | P12: =DATA!B12 | Q12: =Z11 | R12: =AA11 | S12: =Q12+R12 | T12: =DATA!D12 | U12: =DATA!G12 | V12: =Q12*(1+T12) | W12: =R12*(1+U12) | X12: =V12+W12 | Y12: =IF(AND(CONFIG!$B$11="Annual",MONTH(O12)=7),X12*CONFIG!$B$6/12,Y11) | Z12: =IF(X12=0,0,V12-Y12*V12/X12) | AA12: =IF(X12=0,0,W12-Y12*W12/X12) | AC12: =DATA!A12 | AD12: =DATA!B12 | AE12: =AN11 | AF12: =AO11 | AG12: =AE12+AF12 | AH12: =DATA!E12 | AI12: =DATA!G12 | AJ12: =AE12*(1+AH12) | AK12: =AF12*(1+AI12) | AL12: =AJ12+AK12 | AM12: =IF(AND(CONFIG!$B$11="Annual",MONTH(AC12)=7),AL12*CONFIG!$B$6/12,AM11) | AN12: =IF(AL12=0,0,AJ12-AM12*AJ12/AL12) | AO12: =IF(AL12=0,0,AK12-AM12*AK12/AL12)
A13: =DATA!A13 | B13: =DATA!B13 | C13: =L12 | D13: =M12 | E13: =C13+D13 | F13: =DATA!C13 | G13: =DATA!G13 | H13: =C13*(1+F13) | I13: =D13*(1+G13) | J13: =H13+I13 | K13: =IF(AND(CONFIG!$B$11="Annual",MONTH(A13)=7),J13*CONFIG!$B$6/12,K12) | L13: =IF(J13=0,0,H13-K13*H13/J13) | M13: =IF(J13=0,0,I13-K13*I13/J13) | O13: =DATA!A13 | P13: =DATA!B13 | Q13: =Z12 | R13: =AA12 | S13: =Q13+R13 | T13: =DATA!D13 | U13: =DATA!G13 | V13: =Q13*(1+T13) | W13: =R13*(1+U13) | X13: =V13+W13 | Y13: =IF(AND(CONFIG!$B$11="Annual",MONTH(O13)=7),X13*CONFIG!$B$6/12,Y12) | Z13: =IF(X13=0,0,V13-Y13*V13/X13) | AA13: =IF(X13=0,0,W13-Y13*W13/X13) | AC13: =DATA!A13 | AD13: =DATA!B13 | AE13: =AN12 | AF13: =AO12 | AG13: =AE13+AF13 | AH13: =DATA!E13 | AI13: =DATA!G13 | AJ13: =AE13*(1+AH13) | AK13: =AF13*(1+AI13) | AL13: =AJ13+AK13 | AM13: =IF(AND(CONFIG!$B$11="Annual",MONTH(AC13)=7),AL13*CONFIG!$B$6/12,AM12) | AN13: =IF(AL13=0,0,AJ13-AM13*AJ13/AL13) | AO13: =IF(AL13=0,0,AK13-AM13*AK13/AL13)
A14: =DATA!A14 | B14: =DATA!B14 | C14: =L13 | D14: =M13 | E14: =C14+D14 | F14: =DATA!C14 | G14: =DATA!G14 | H14: =C14*(1+F14) | I14: =D14*(1+G14) | J14: =H14+I14 | K14: =IF(AND(CONFIG!$B$11="Annual",MONTH(A14)=7),J14*CONFIG!$B$6/12,K13) | L14: =IF(J14=0,0,H14-K14*H14/J14) | M14: =IF(J14=0,0,I14-K14*I14/J14) | O14: =DATA!A14 | P14: =DATA!B14 | Q14: =Z13 | R14: =AA13 | S14: =Q14+R14 | T14: =DATA!D14 | U14: =DATA!G14 | V14: =Q14*(1+T14) | W14: =R14*(1+U14) | X14: =V14+W14 | Y14: =IF(AND(CONFIG!$B$11="Annual",MONTH(O14)=7),X14*CONFIG!$B$6/12,Y13) | Z14: =IF(X14=0,0,V14-Y14*V14/X14) | AA14: =IF(X14=0,0,W14-Y14*W14/X14) | AC14: =DATA!A14 | AD14: =DATA!B14 | AE14: =AN13 | AF14: =AO13 | AG14: =AE14+AF14 | AH14: =DATA!E14 | AI14: =DATA!G14 | AJ14: =AE14*(1+AH14) | AK14: =AF14*(1+AI14) | AL14: =AJ14+AK14 | AM14: =IF(AND(CONFIG!$B$11="Annual",MONTH(AC14)=7),AL14*CONFIG!$B$6/12,AM13) | AN14: =IF(AL14=0,0,AJ14-AM14*AJ14/AL14) | AO14: =IF(AL14=0,0,AK14-AM14*AK14/AL14)
A15: =DATA!A15 | B15: =DATA!B15 | C15: =L14 | D15: =M14 | E15: =C15+D15 | F15: =DATA!C15 | G15: =DATA!G15 | H15: =C15*(1+F15) | I15: =D15*(1+G15) | J15: =H15+I15 | K15: =IF(AND(CONFIG!$B$11="Annual",MONTH(A15)=7),J15*CONFIG!$B$6/12,K14) | L15: =IF(J15=0,0,H15-K15*H15/J15) | M15: =IF(J15=0,0,I15-K15*I15/J15) | O15: =DATA!A15 | P15: =DATA!B15 | Q15: =Z14 | R15: =AA14 | S15: =Q15+R15 | T15: =DATA!D15 | U15: =DATA!G15 | V15: =Q15*(1+T15) | W15: =R15*(1+U15) | X15: =V15+W15 | Y15: =IF(AND(CONFIG!$B$11="Annual",MONTH(O15)=7),X15*CONFIG!$B$6/12,Y14) | Z15: =IF(X15=0,0,V15-Y15*V15/X15) | AA15: =IF(X15=0,0,W15-Y15*W15/X15) | AC15: =DATA!A15 | AD15: =DATA!B15 | AE15: =AN14 | AF15: =AO14 | AG15: =AE15+AF15 | AH15: =DATA!E15 | AI15: =DATA!G15 | AJ15: =AE15*(1+AH15) | AK15: =AF15*(1+AI15) | AL15: =AJ15+AK15 | AM15: =IF(AND(CONFIG!$B$11="Annual",MONTH(AC15)=7),AL15*CONFIG!$B$6/12,AM14) | AN15: =IF(AL15=0,0,AJ15-AM15*AJ15/AL15) | AO15: =IF(AL15=0,0,AK15-AM15*AK15/AL15)
A16: =DATA!A16 | B16: =DATA!B16 | C16: =L15 | D16: =M15 | E16: =C16+D16 | F16: =DATA!C16 | G16: =DATA!G16 | H16: =C16*(1+F16) | I16: =D16*(1+G16) | J16: =H16+I16 | K16: =IF(AND(CONFIG!$B$11="Annual",MONTH(A16)=7),J16*CONFIG!$B$6/12,K15) | L16: =IF(J16=0,0,H16-K16*H16/J16) | M16: =IF(J16=0,0,I16-K16*I16/J16) | O16: =DATA!A16 | P16: =DATA!B16 | Q16: =Z15 | R16: =AA15 | S16: =Q16+R16 | T16: =DATA!D16 | U16: =DATA!G16 | V16: =Q16*(1+T16) | W16: =R16*(1+U16) | X16: =V16+W16 | Y16: =IF(AND(CONFIG!$B$11="Annual",MONTH(O16)=7),X16*CONFIG!$B$6/12,Y15) | Z16: =IF(X16=0,0,V16-Y16*V16/X16) | AA16: =IF(X16=0,0,W16-Y16*W16/X16) | AC16: =DATA!A16 | AD16: =DATA!B16 | AE16: =AN15 | AF16: =AO15 | AG16: =AE16+AF16 | AH16: =DATA!E16 | AI16: =DATA!G16 | AJ16: =AE16*(1+AH16) | AK16: =AF16*(1+AI16) | AL16: =AJ16+AK16 | AM16: =IF(AND(CONFIG!$B$11="Annual",MONTH(AC16)=7),AL16*CONFIG!$B$6/12,AM15) | AN16: =IF(AL16=0,0,AJ16-AM16*AJ16/AL16) | AO16: =IF(AL16=0,0,AK16-AM16*AK16/AL16)
... A283: =DATA!A283 | B283: =DATA!B283 | C283: =L282 | D283: =M282 | E283: =C283+D283 | F283: =DATA!C283 | G283: =DATA!G283 | H283: =C283*(1+F283) | I283: =D283*(1+G283) | J283: =H283+I283 | K283: =IF(AND(CONFIG!$B$11="Annual",MONTH(A283)=7),J283*CONFIG!$B$6/12,K282) | L283: =IF(J283=0,0,H283-K283*H283/J283) | M283: =IF(J283=0,0,I283-K283*I283/J283) | O283: =DATA!A283 | P283: =DATA!B283 | Q283: =Z282 | R283: =AA282 | S283: =Q283+R283 | T283: =DATA!D283 | U283: =DATA!G283 | V283: =Q283*(1+T283) | W283: =R283*(1+U283) | X283: =V283+W283 | Y283: =IF(AND(CONFIG!$B$11="Annual",MONTH(O283)=7),X283*CONFIG!$B$6/12,Y282) | Z283: =IF(X283=0,0,V283-Y283*V283/X283) | AA283: =IF(X283=0,0,W283-Y283*W283/X283) | AC283: =DATA!A283 | AD283: =DATA!B283 | AE283: =AN282 | AF283: =AO282 | AG283: =AE283+AF283 | AH283: =DATA!E283 | AI283: =DATA!G283 | AJ283: =AE283*(1+AH283) | AK283: =AF283*(1+AI283) | AL283: =AJ283+AK283 | AM283: =IF(AND(CONFIG!$B$11="Annual",MONTH(AC283)=7),AL283*CONFIG!$B$6/12,AM282) | AN283: =IF(AL283=0,0,AJ283-AM283*AJ283/AL283) | AO283: =IF(AL283=0,0,AK283-AM283*AK283/AL283)

Sheet DASHBOARD
A1: Hostplus Retirement Portfolios — Back-Test Results
A3: Summary Metrics
B4: Growth RP | C4: Growth Bench | D4: Balanced RP | E4: Balanced Bench | F4: Conservative RP | G4: Conservative Bench
A5: Starting Balance | B5: =CONFIG!$B$5 | C5: =CONFIG!$B$5 | D5: =CONFIG!$B$5 | E5: =CONFIG!$B$5 | F5: =CONFIG!$B$5 | G5: =CONFIG!$B$5
A6: Ending Balance | B6: =ENGINE!O283+ENGINE!P283 | C6: =COMPARISON!L283+COMPARISON!M283 | D6: =ENGINE!AF283+ENGINE!AG283 | E6: =COMPARISON!Z283+COMPARISON!AA283 | F6: =ENGINE!AW283+ENGINE!AX283 | G6: =COMPARISON!AN283+COMPARISON!AO283
A7: Total Return | B7: =(ENGINE!O283+ENGINE!P283)/CONFIG!$B$5-1 | C7: =(COMPARISON!L283+COMPARISON!M283)/CONFIG!$B$5-1 | D7: =(ENGINE!AF283+ENGINE!AG283)/CONFIG!$B$5-1 | E7: =(COMPARISON!Z283+COMPARISON!AA283)/CONFIG!$B$5-1 | F7: =(ENGINE!AW283+ENGINE!AX283)/CONFIG!$B$5-1 | G7: =(COMPARISON!AN283+COMPARISON!AO283)/CONFIG!$B$5-1
A8: Total Income Paid | B8: =SUM(ENGINE!J4:J283) | C8: =SUM(COMPARISON!K4:K283) | D8: =SUM(ENGINE!AA4:AA283) | E8: =SUM(COMPARISON!Y4:Y283) | F8: =SUM(ENGINE!AR4:AR283) | G8: =SUM(COMPARISON!AM4:AM283)
A9: Rebalance Events | B9: =COUNTIF(ENGINE!N4:N283,"Y") | C9: N/A | D9: =COUNTIF(ENGINE!AE4:AE283,"Y") | E9: N/A | F9: =COUNTIF(ENGINE!AV4:AV283,"Y") | G9: N/A
A12: Portfolio Value Over Time
A30: Growth: Retirement Portfolio vs Benchmark
A48: CPIplus Weight Over Time (Growth Portfolio)
